Traceback (most recent call last):
  File "/var/pythonapps/downloadFiles.py", line 3, in <module>
    import pycron
ModuleNotFoundError: No module named 'pycron'
Traceback (most recent call last):
  File "/var/pythonapps/downloadFiles.py", line 3, in <module>
    import pycron
ModuleNotFoundError: No module named 'pycron'
Traceback (most recent call last):
  File "/var/pythonapps/downloadFiles.py", line 3, in <module>
    import pycron
ModuleNotFoundError: No module named 'pycron'
Traceback (most recent call last):
  File "/var/pythonapps/downloadFiles.py", line 3, in <module>
    import pycron
ModuleNotFoundError: No module named 'pycron'
Traceback (most recent call last):
  File "/var/pythonapps/downloadFiles.py", line 159, in <module>
    pycron.start()
  File "/var/pythonapps/.venv/lib/python3.11/site-packages/pycron/__init__.py", line 104, in start
    time.sleep(1 - (end_time - start_time))
KeyboardInterrupt
Traceback (most recent call last):
  File "/var/pythonapps/downloadFiles.py", line 159, in <module>
    pycron.start()
  File "/var/pythonapps/.venv/lib/python3.11/site-packages/pycron/__init__.py", line 104, in start
    time.sleep(1 - (end_time - start_time))
KeyboardInterrupt
Traceback (most recent call last):
  File "/var/pythonapps/downloadFiles.py", line 159, in <module>
    pycron.start()
  File "/var/pythonapps/.venv/lib/python3.11/site-packages/pycron/__init__.py", line 104, in start
    time.sleep(1 - (end_time - start_time))
KeyboardInterrupt
Traceback (most recent call last):
  File "/var/pythonapps/downloadFiles.py", line 159, in <module>
    pycron.start()
  File "/var/pythonapps/.venv/lib/python3.11/site-packages/pycron/__init__.py", line 104, in start
    time.sleep(1 - (end_time - start_time))
KeyboardInterrupt
Traceback (most recent call last):
  File "/var/pythonapps/downloadFiles.py", line 159, in <module>
    pycron.start()
  File "/var/pythonapps/.venv/lib/python3.11/site-packages/pycron/__init__.py", line 104, in start
    time.sleep(1 - (end_time - start_time))
KeyboardInterrupt
Traceback (most recent call last):
  File "/var/pythonapps/downloadFiles.py", line 159, in <module>
    pycron.start()
  File "/var/pythonapps/.venv/lib/python3.11/site-packages/pycron/__init__.py", line 104, in start
    time.sleep(1 - (end_time - start_time))
KeyboardInterrupt
Exception ignored in: <module 'threading' from '/usr/lib/python3.11/threading.py'>
Traceback (most recent call last):
  File "/usr/lib/python3.11/threading.py", line 1583, in _shutdown
    lock.acquire()
KeyboardInterrupt: 
Traceback (most recent call last):
  File "/var/pythonapps/downloadFiles.py", line 3, in <module>
    import pycron
ModuleNotFoundError: No module named 'pycron'
Traceback (most recent call last):
  File "/var/pythonapps/downloadFiles.py", line 3, in <module>
    import pycron
ModuleNotFoundError: No module named 'pycron'
Traceback (most recent call last):
  File "/var/pythonapps/downloadFiles.py", line 3, in <module>
    import pycron
ModuleNotFoundError: No module named 'pycron'
Traceback (most recent call last):
  File "/var/pythonapps/downloadFiles.py", line 3, in <module>
    import pycron
ModuleNotFoundError: No module named 'pycron'
Exception in thread Thread-1:
Traceback (most recent call last):
  File "/usr/lib/python3.11/threading.py", line 1038, in _bootstrap_inner
    self.run()
  File "/var/pythonapps/.venv/lib/python3.11/site-packages/pycron/__init__.py", line 24, in run
    asyncio.run(self.function(datetime.now()))
  File "/usr/lib/python3.11/asyncio/runners.py", line 190, in run
    return runner.run(main)
           ^^^^^^^^^^^^^^^^
  File "/usr/lib/python3.11/asyncio/runners.py", line 118, in run
    return self._loop.run_until_complete(task)
           ^^^^^^^^^^^^^^^^^^^^^^^^^^^^^^^^^^^
  File "/usr/lib/python3.11/asyncio/base_events.py", line 653, in run_until_complete
    return future.result()
           ^^^^^^^^^^^^^^^
  File "/var/pythonapps/downloadFiles.py", line 160, in downloadFiles
    ModifyFiles().apolloMod()
  File "/var/pythonapps/Classes/ModifyFiles.py", line 73, in apolloMod
    subst_dict['ean'] = item['EAN']
                        ~~~~^^^^^^^
KeyError: 'EAN'
Exception in thread Thread-1:
Traceback (most recent call last):
  File "/usr/lib/python3.11/threading.py", line 1038, in _bootstrap_inner
    self.run()
  File "/var/pythonapps/.venv/lib/python3.11/site-packages/pycron/__init__.py", line 24, in run
    asyncio.run(self.function(datetime.now()))
  File "/usr/lib/python3.11/asyncio/runners.py", line 190, in run
    return runner.run(main)
           ^^^^^^^^^^^^^^^^
  File "/usr/lib/python3.11/asyncio/runners.py", line 118, in run
    return self._loop.run_until_complete(task)
           ^^^^^^^^^^^^^^^^^^^^^^^^^^^^^^^^^^^
  File "/usr/lib/python3.11/asyncio/base_events.py", line 653, in run_until_complete
    return future.result()
           ^^^^^^^^^^^^^^^
  File "/var/pythonapps/downloadFiles.py", line 160, in downloadFiles
    ModifyFiles().verkkokouppaMod()
    ^^^^^^^^^^^^^^^^^^^^^^^^^
  File "/var/pythonapps/Classes/ModifyFiles.py", line 73, in apolloMod
    subst_dict['ean'] = item['EAN']
                        ~~~~^^^^^^^
KeyError: 'EAN'
Exception in thread Thread-1:
Traceback (most recent call last):
  File "/var/pythonapps/Classes/ModifyFiles.py", line 134, in actionMod
    if int(item['ean']) not in unique_ean_list and int(item['stock']) >= min_stock:
       ^^^^^^^^^^^^^^^^
ValueError: invalid literal for int() with base 10: ''

During handling of the above exception, another exception occurred:

Traceback (most recent call last):
  File "/usr/lib/python3.11/threading.py", line 1038, in _bootstrap_inner
    self.run()
  File "/var/pythonapps/.venv/lib/python3.11/site-packages/pycron/__init__.py", line 24, in run
    asyncio.run(self.function(datetime.now()))
  File "/usr/lib/python3.11/asyncio/runners.py", line 190, in run
    return runner.run(main)
           ^^^^^^^^^^^^^^^^
  File "/usr/lib/python3.11/asyncio/runners.py", line 118, in run
    return self._loop.run_until_complete(task)
           ^^^^^^^^^^^^^^^^^^^^^^^^^^^^^^^^^^^
  File "/usr/lib/python3.11/asyncio/base_events.py", line 653, in run_until_complete
    return future.result()
           ^^^^^^^^^^^^^^^
  File "/var/pythonapps/downloadFiles.py", line 163, in downloadFiles
    ModifyFiles().actionMod()
  File "/var/pythonapps/Classes/ModifyFiles.py", line 137, in actionMod
    print(e)
ValueError: I/O operation on closed file.
Traceback (most recent call last):
  File "/var/pythonapps/downloadFiles.py", line 180, in <module>
    pycron.start()
  File "/var/pythonapps/.venv/lib/python3.11/site-packages/pycron/__init__.py", line 104, in start
    time.sleep(1 - (end_time - start_time))
KeyboardInterrupt
Exception in thread Thread-1:
Traceback (most recent call last):
  File "/usr/lib/python3.11/threading.py", line 1038, in _bootstrap_inner
    self.run()
  File "/var/pythonapps/.venv/lib/python3.11/site-packages/pycron/__init__.py", line 24, in run
    asyncio.run(self.function(datetime.now()))
  File "/usr/lib/python3.11/asyncio/runners.py", line 190, in run
    return runner.run(main)
           ^^^^^^^^^^^^^^^^
  File "/usr/lib/python3.11/asyncio/runners.py", line 118, in run
    return self._loop.run_until_complete(task)
           ^^^^^^^^^^^^^^^^^^^^^^^^^^^^^^^^^^^
  File "/usr/lib/python3.11/asyncio/base_events.py", line 653, in run_until_complete
    return future.result()
           ^^^^^^^^^^^^^^^
  File "/var/pythonapps/downloadFiles.py", line 162, in downloadFiles
    ModifyFiles().apolloMod()
  File "/var/pythonapps/Classes/ModifyFiles.py", line 75, in apolloMod
    subst_dict['sku'] = item['Part Number']
                        ~~~~^^^^^^^^^^^^^^^
KeyError: 'Part Number'
Exception in thread Thread-1:
Traceback (most recent call last):
  File "/usr/lib/python3.11/threading.py", line 1038, in _bootstrap_inner
    self.run()
  File "/var/pythonapps/.venv/lib/python3.11/site-packages/pycron/__init__.py", line 24, in run
    asyncio.run(self.function(datetime.now()))
  File "/usr/lib/python3.11/asyncio/runners.py", line 190, in run
    return runner.run(main)
           ^^^^^^^^^^^^^^^^
  File "/usr/lib/python3.11/asyncio/runners.py", line 118, in run
    return self._loop.run_until_complete(task)
           ^^^^^^^^^^^^^^^^^^^^^^^^^^^^^^^^^^^
  File "/usr/lib/python3.11/asyncio/base_events.py", line 653, in run_until_complete
    return future.result()
           ^^^^^^^^^^^^^^^
  File "/var/pythonapps/downloadFiles.py", line 162, in downloadFiles
    ModifyFiles().apolloMod() #
    ^^^^^^^^^^^^^^^^^^^^^^^^^
  File "/var/pythonapps/Classes/ModifyFiles.py", line 75, in apolloMod
    subst_dict['sku'] = item['Part Number']
                        ~~~~^^^^^^^^^^^^^^^
KeyError: 'Part Number'
Exception in thread Thread-2:
Traceback (most recent call last):
  File "/usr/lib/python3.11/threading.py", line 1038, in _bootstrap_inner
    self.run()
  File "/var/pythonapps/.venv/lib/python3.11/site-packages/pycron/__init__.py", line 24, in run
    asyncio.run(self.function(datetime.now()))
  File "/usr/lib/python3.11/asyncio/runners.py", line 190, in run
    return runner.run(main)
           ^^^^^^^^^^^^^^^^
  File "/usr/lib/python3.11/asyncio/runners.py", line 118, in run
    return self._loop.run_until_complete(task)
           ^^^^^^^^^^^^^^^^^^^^^^^^^^^^^^^^^^^
  File "/usr/lib/python3.11/asyncio/base_events.py", line 653, in run_until_complete
    return future.result()
           ^^^^^^^^^^^^^^^
  File "/var/pythonapps/downloadFiles.py", line 162, in downloadFiles
    ModifyFiles().apolloMod() #
    ^^^^^^^^^^^^^^^^^^^^^^^^^
  File "/var/pythonapps/Classes/ModifyFiles.py", line 75, in apolloMod
    subst_dict['sku'] = item['Part Number']
                        ~~~~^^^^^^^^^^^^^^^
KeyError: 'Part Number'
Exception in thread Thread-3:
Traceback (most recent call last):
  File "/usr/lib/python3.11/threading.py", line 1038, in _bootstrap_inner
    self.run()
  File "/var/pythonapps/.venv/lib/python3.11/site-packages/pycron/__init__.py", line 24, in run
    asyncio.run(self.function(datetime.now()))
  File "/usr/lib/python3.11/asyncio/runners.py", line 190, in run
    return runner.run(main)
           ^^^^^^^^^^^^^^^^
  File "/usr/lib/python3.11/asyncio/runners.py", line 118, in run
    return self._loop.run_until_complete(task)
           ^^^^^^^^^^^^^^^^^^^^^^^^^^^^^^^^^^^
  File "/usr/lib/python3.11/asyncio/base_events.py", line 653, in run_until_complete
    return future.result()
           ^^^^^^^^^^^^^^^
  File "/var/pythonapps/downloadFiles.py", line 162, in downloadFiles
    ModifyFiles().apolloMod() #
    ^^^^^^^^^^^^^^^^^^^^^^^^^
  File "/var/pythonapps/Classes/ModifyFiles.py", line 75, in apolloMod
    subst_dict['sku'] = item['Part Number']
                        ~~~~^^^^^^^^^^^^^^^
KeyError: 'Part Number'
Exception in thread Thread-4:
Traceback (most recent call last):
  File "/usr/lib/python3.11/threading.py", line 1038, in _bootstrap_inner
    self.run()
  File "/var/pythonapps/.venv/lib/python3.11/site-packages/pycron/__init__.py", line 24, in run
    asyncio.run(self.function(datetime.now()))
  File "/usr/lib/python3.11/asyncio/runners.py", line 190, in run
    return runner.run(main)
           ^^^^^^^^^^^^^^^^
  File "/usr/lib/python3.11/asyncio/runners.py", line 118, in run
    return self._loop.run_until_complete(task)
           ^^^^^^^^^^^^^^^^^^^^^^^^^^^^^^^^^^^
  File "/usr/lib/python3.11/asyncio/base_events.py", line 653, in run_until_complete
    return future.result()
           ^^^^^^^^^^^^^^^
  File "/var/pythonapps/downloadFiles.py", line 162, in downloadFiles
    ModifyFiles().apolloMod() #
    ^^^^^^^^^^^^^^^^^^^^^^^^^
  File "/var/pythonapps/Classes/ModifyFiles.py", line 75, in apolloMod
    subst_dict['sku'] = item['Part Number']
                        ~~~~^^^^^^^^^^^^^^^
KeyError: 'Part Number'
Exception in thread Thread-1:
Traceback (most recent call last):
  File "/usr/lib/python3.11/threading.py", line 1038, in _bootstrap_inner
    self.run()
  File "/var/pythonapps/.venv/lib/python3.11/site-packages/pycron/__init__.py", line 24, in run
    asyncio.run(self.function(datetime.now()))
  File "/usr/lib/python3.11/asyncio/runners.py", line 190, in run
    return runner.run(main)
           ^^^^^^^^^^^^^^^^
  File "/usr/lib/python3.11/asyncio/runners.py", line 118, in run
    return self._loop.run_until_complete(task)
           ^^^^^^^^^^^^^^^^^^^^^^^^^^^^^^^^^^^
  File "/usr/lib/python3.11/asyncio/base_events.py", line 653, in run_until_complete
    return future.result()
           ^^^^^^^^^^^^^^^
  File "/var/pythonapps/downloadFiles.py", line 162, in downloadFiles
    ModifyFiles().apolloMod() #
    ^^^^^^^^^^^^^^^^^^^^^^^^^
  File "/var/pythonapps/Classes/ModifyFiles.py", line 75, in apolloMod
    subst_dict['sku'] = item['Part Number']
                        ~~~~^^^^^^^^^^^^^^^
KeyError: 'Part Number'
Exception in thread Thread-2:
Traceback (most recent call last):
  File "/usr/lib/python3.11/threading.py", line 1038, in _bootstrap_inner
    self.run()
  File "/var/pythonapps/.venv/lib/python3.11/site-packages/pycron/__init__.py", line 24, in run
    asyncio.run(self.function(datetime.now()))
  File "/usr/lib/python3.11/asyncio/runners.py", line 190, in run
    return runner.run(main)
           ^^^^^^^^^^^^^^^^
  File "/usr/lib/python3.11/asyncio/runners.py", line 118, in run
    return self._loop.run_until_complete(task)
           ^^^^^^^^^^^^^^^^^^^^^^^^^^^^^^^^^^^
  File "/usr/lib/python3.11/asyncio/base_events.py", line 653, in run_until_complete
    return future.result()
           ^^^^^^^^^^^^^^^
  File "/var/pythonapps/downloadFiles.py", line 162, in downloadFiles
    ModifyFiles().apolloMod() #
    ^^^^^^^^^^^^^^^^^^^^^^^^^
  File "/var/pythonapps/Classes/ModifyFiles.py", line 75, in apolloMod
    subst_dict['sku'] = item['Part Number']
                        ~~~~^^^^^^^^^^^^^^^
KeyError: 'Part Number'
Exception in thread Thread-3:
Traceback (most recent call last):
  File "/usr/lib/python3.11/threading.py", line 1038, in _bootstrap_inner
    self.run()
  File "/var/pythonapps/.venv/lib/python3.11/site-packages/pycron/__init__.py", line 24, in run
    asyncio.run(self.function(datetime.now()))
  File "/usr/lib/python3.11/asyncio/runners.py", line 190, in run
    return runner.run(main)
           ^^^^^^^^^^^^^^^^
  File "/usr/lib/python3.11/asyncio/runners.py", line 118, in run
    return self._loop.run_until_complete(task)
           ^^^^^^^^^^^^^^^^^^^^^^^^^^^^^^^^^^^
  File "/usr/lib/python3.11/asyncio/base_events.py", line 653, in run_until_complete
    return future.result()
           ^^^^^^^^^^^^^^^
  File "/var/pythonapps/downloadFiles.py", line 162, in downloadFiles
    ModifyFiles().apolloMod() #
    ^^^^^^^^^^^^^^^^^^^^^^^^^
  File "/var/pythonapps/Classes/ModifyFiles.py", line 75, in apolloMod
    subst_dict['sku'] = item['Part Number']
                        ~~~~^^^^^^^^^^^^^^^
KeyError: 'Part Number'
Exception in thread Thread-1:
Traceback (most recent call last):
  File "/usr/lib/python3.11/threading.py", line 1038, in _bootstrap_inner
    self.run()
  File "/var/pythonapps/.venv/lib/python3.11/site-packages/pycron/__init__.py", line 24, in run
    asyncio.run(self.function(datetime.now()))
  File "/usr/lib/python3.11/asyncio/runners.py", line 190, in run
    return runner.run(main)
           ^^^^^^^^^^^^^^^^
  File "/usr/lib/python3.11/asyncio/runners.py", line 118, in run
    return self._loop.run_until_complete(task)
           ^^^^^^^^^^^^^^^^^^^^^^^^^^^^^^^^^^^
  File "/usr/lib/python3.11/asyncio/base_events.py", line 653, in run_until_complete
    return future.result()
           ^^^^^^^^^^^^^^^
  File "/var/pythonapps/downloadFiles.py", line 163, in downloadFiles
    ModifyFiles().actionMod() #
    ^^^^^^^^^^^^^^^^^^^^^^^^^
  File "/var/pythonapps/Classes/ModifyFiles.py", line 120, in actionMod
    subst_dict['ean'] = item['EAN']
                        ~~~~^^^^^^^
KeyError: 'EAN'
Traceback (most recent call last):
  File "/var/pythonapps/downloadFiles.py", line 181, in <module>
    pycron.start()
  File "/var/pythonapps/.venv/lib/python3.11/site-packages/pycron/__init__.py", line 104, in start
    time.sleep(1 - (end_time - start_time))
KeyboardInterrupt
Traceback (most recent call last):
  File "/var/pythonapps/downloadFiles.py", line 181, in <module>
    pycron.start()
  File "/var/pythonapps/.venv/lib/python3.11/site-packages/pycron/__init__.py", line 104, in start
    time.sleep(1 - (end_time - start_time))
KeyboardInterrupt
Exception ignored in: <module 'threading' from '/usr/lib/python3.11/threading.py'>
Traceback (most recent call last):
  File "/usr/lib/python3.11/threading.py", line 1583, in _shutdown
    lock.acquire()
KeyboardInterrupt: 
Exception in thread Thread-1:
Traceback (most recent call last):
  File "/usr/lib/python3.11/threading.py", line 1038, in _bootstrap_inner
    self.run()
  File "/var/pythonapps/.venv/lib/python3.11/site-packages/pycron/__init__.py", line 24, in run
    asyncio.run(self.function(datetime.now()))
  File "/usr/lib/python3.11/asyncio/runners.py", line 190, in run
    return runner.run(main)
           ^^^^^^^^^^^^^^^^
  File "/usr/lib/python3.11/asyncio/runners.py", line 118, in run
    return self._loop.run_until_complete(task)
           ^^^^^^^^^^^^^^^^^^^^^^^^^^^^^^^^^^^
  File "/usr/lib/python3.11/asyncio/base_events.py", line 653, in run_until_complete
    return future.result()
           ^^^^^^^^^^^^^^^
  File "/var/pythonapps/downloadFiles.py", line 173, in downloadFiles
    MenageSQL.dropTable(conn, table_name)
TypeError: MenageSQL.dropTable() missing 1 required positional argument: 'table_name'
Traceback (most recent call last):
  File "/var/pythonapps/downloadFiles.py", line 181, in <module>
    pycron.start()
  File "/var/pythonapps/.venv/lib/python3.11/site-packages/pycron/__init__.py", line 104, in start
    time.sleep(1 - (end_time - start_time))
KeyboardInterrupt
Traceback (most recent call last):
  File "/var/pythonapps/downloadFiles.py", line 181, in <module>
    pycron.start()
  File "/var/pythonapps/.venv/lib/python3.11/site-packages/pycron/__init__.py", line 104, in start
    time.sleep(1 - (end_time - start_time))
KeyboardInterrupt
Exception in thread Thread-14:
Traceback (most recent call last):
  File "/usr/lib/python3.11/threading.py", line 1038, in _bootstrap_inner
    self.run()
  File "/var/pythonapps/.venv/lib/python3.11/site-packages/pycron/__init__.py", line 24, in run
    asyncio.run(self.function(datetime.now()))
  File "/usr/lib/python3.11/asyncio/runners.py", line 190, in run
    return runner.run(main)
           ^^^^^^^^^^^^^^^^
  File "/usr/lib/python3.11/asyncio/runners.py", line 118, in run
    return self._loop.run_until_complete(task)
           ^^^^^^^^^^^^^^^^^^^^^^^^^^^^^^^^^^^
  File "/usr/lib/python3.11/asyncio/base_events.py", line 653, in run_until_complete
    return future.result()
           ^^^^^^^^^^^^^^^
  File "/var/pythonapps/downloadFiles.py", line 163, in downloadFiles
    ModifyFiles().actionMod() #
    ^^^^^^^^^^^^^^^^^^^^^^^^^
  File "/var/pythonapps/Classes/ModifyFiles.py", line 120, in actionMod
    subst_dict['ean'] = item['EAN']
                        ~~~~^^^^^^^
KeyError: 'EAN'
Exception in thread Thread-17:
Traceback (most recent call last):
  File "/usr/lib/python3.11/threading.py", line 1038, in _bootstrap_inner
    self.run()
  File "/var/pythonapps/.venv/lib/python3.11/site-packages/pycron/__init__.py", line 24, in run
    asyncio.run(self.function(datetime.now()))
  File "/usr/lib/python3.11/asyncio/runners.py", line 190, in run
    return runner.run(main)
           ^^^^^^^^^^^^^^^^
  File "/usr/lib/python3.11/asyncio/runners.py", line 118, in run
    return self._loop.run_until_complete(task)
           ^^^^^^^^^^^^^^^^^^^^^^^^^^^^^^^^^^^
  File "/usr/lib/python3.11/asyncio/base_events.py", line 653, in run_until_complete
    return future.result()
           ^^^^^^^^^^^^^^^
  File "/var/pythonapps/downloadFiles.py", line 163, in downloadFiles
    ModifyFiles().domitechMod() #
    ^^^^^^^^^^^^^^^^^^^^^^^^^
  File "/var/pythonapps/Classes/ModifyFiles.py", line 120, in actionMod
    subst_dict['ean'] = item['EAN']
                        ~~~~^^^^^^^
KeyError: 'EAN'
Exception in thread Thread-26:
Traceback (most recent call last):
  File "/usr/lib/python3.11/threading.py", line 1038, in _bootstrap_inner
    self.run()
  File "/var/pythonapps/.venv/lib/python3.11/site-packages/pycron/__init__.py", line 24, in run
    asyncio.run(self.function(datetime.now()))
  File "/usr/lib/python3.11/asyncio/runners.py", line 190, in run
    return runner.run(main)
           ^^^^^^^^^^^^^^^^
  File "/usr/lib/python3.11/asyncio/runners.py", line 118, in run
    return self._loop.run_until_complete(task)
           ^^^^^^^^^^^^^^^^^^^^^^^^^^^^^^^^^^^
  File "/usr/lib/python3.11/asyncio/base_events.py", line 653, in run_until_complete
    return future.result()
           ^^^^^^^^^^^^^^^
  File "/var/pythonapps/downloadFiles.py", line 163, in downloadFiles
    ModifyFiles().domitechMod() #
    ^^^^^^^^^^^^^^^^^^^^^^^^^
  File "/var/pythonapps/Classes/ModifyFiles.py", line 120, in actionMod
    subst_dict['ean'] = item['EAN']
                        ~~~~^^^^^^^
KeyError: 'EAN'
Exception in thread Thread-50:
Traceback (most recent call last):
  File "/usr/lib/python3.11/threading.py", line 1038, in _bootstrap_inner
    self.run()
  File "/var/pythonapps/.venv/lib/python3.11/site-packages/pycron/__init__.py", line 24, in run
    asyncio.run(self.function(datetime.now()))
  File "/usr/lib/python3.11/asyncio/runners.py", line 190, in run
    return runner.run(main)
           ^^^^^^^^^^^^^^^^
  File "/usr/lib/python3.11/asyncio/runners.py", line 118, in run
    return self._loop.run_until_complete(task)
           ^^^^^^^^^^^^^^^^^^^^^^^^^^^^^^^^^^^
  File "/usr/lib/python3.11/asyncio/base_events.py", line 653, in run_until_complete
    return future.result()
           ^^^^^^^^^^^^^^^
  File "/var/pythonapps/downloadFiles.py", line 163, in downloadFiles
    ModifyFiles().domitechMod() #
    ^^^^^^^^^^^^^^^^^^^^^^^^^
  File "/var/pythonapps/Classes/ModifyFiles.py", line 120, in actionMod
    subst_dict['ean'] = item['EAN']
                        ~~~~^^^^^^^
KeyError: 'EAN'
Exception in thread Thread-53:
Traceback (most recent call last):
  File "/usr/lib/python3.11/threading.py", line 1038, in _bootstrap_inner
    self.run()
  File "/var/pythonapps/.venv/lib/python3.11/site-packages/pycron/__init__.py", line 24, in run
    asyncio.run(self.function(datetime.now()))
  File "/usr/lib/python3.11/asyncio/runners.py", line 190, in run
    return runner.run(main)
           ^^^^^^^^^^^^^^^^
  File "/usr/lib/python3.11/asyncio/runners.py", line 118, in run
    return self._loop.run_until_complete(task)
           ^^^^^^^^^^^^^^^^^^^^^^^^^^^^^^^^^^^
  File "/usr/lib/python3.11/asyncio/base_events.py", line 653, in run_until_complete
    return future.result()
           ^^^^^^^^^^^^^^^
  File "/var/pythonapps/downloadFiles.py", line 163, in downloadFiles
    ModifyFiles().domitechMod() #
    ^^^^^^^^^^^^^^^^^^^^^^^^^
  File "/var/pythonapps/Classes/ModifyFiles.py", line 120, in actionMod
    subst_dict['ean'] = item['EAN']
                        ~~~~^^^^^^^
KeyError: 'EAN'
Exception in thread Thread-62:
Traceback (most recent call last):
  File "/usr/lib/python3.11/threading.py", line 1038, in _bootstrap_inner
    self.run()
  File "/var/pythonapps/.venv/lib/python3.11/site-packages/pycron/__init__.py", line 24, in run
    asyncio.run(self.function(datetime.now()))
  File "/usr/lib/python3.11/asyncio/runners.py", line 190, in run
    return runner.run(main)
           ^^^^^^^^^^^^^^^^
  File "/usr/lib/python3.11/asyncio/runners.py", line 118, in run
    return self._loop.run_until_complete(task)
           ^^^^^^^^^^^^^^^^^^^^^^^^^^^^^^^^^^^
  File "/usr/lib/python3.11/asyncio/base_events.py", line 653, in run_until_complete
    return future.result()
           ^^^^^^^^^^^^^^^
  File "/var/pythonapps/downloadFiles.py", line 163, in downloadFiles
    ModifyFiles().domitechMod() #
    ^^^^^^^^^^^^^^^^^^^^^^^^^
  File "/var/pythonapps/Classes/ModifyFiles.py", line 120, in actionMod
    subst_dict['ean'] = item['EAN']
                        ~~~~^^^^^^^
KeyError: 'EAN'
Exception in thread Thread-68:
Traceback (most recent call last):
  File "/usr/lib/python3.11/threading.py", line 1038, in _bootstrap_inner
    self.run()
  File "/var/pythonapps/.venv/lib/python3.11/site-packages/pycron/__init__.py", line 24, in run
    asyncio.run(self.function(datetime.now()))
  File "/usr/lib/python3.11/asyncio/runners.py", line 190, in run
    return runner.run(main)
           ^^^^^^^^^^^^^^^^
  File "/usr/lib/python3.11/asyncio/runners.py", line 118, in run
    return self._loop.run_until_complete(task)
           ^^^^^^^^^^^^^^^^^^^^^^^^^^^^^^^^^^^
  File "/usr/lib/python3.11/asyncio/base_events.py", line 653, in run_until_complete
    return future.result()
           ^^^^^^^^^^^^^^^
  File "/var/pythonapps/downloadFiles.py", line 163, in downloadFiles
    ModifyFiles().domitechMod() #
    ^^^^^^^^^^^^^^^^^^^^^^^^^
  File "/var/pythonapps/Classes/ModifyFiles.py", line 120, in actionMod
    subst_dict['ean'] = item['EAN']
                        ~~~~^^^^^^^
KeyError: 'EAN'
Exception in thread Thread-80:
Traceback (most recent call last):
  File "/usr/lib/python3.11/threading.py", line 1038, in _bootstrap_inner
    self.run()
  File "/var/pythonapps/.venv/lib/python3.11/site-packages/pycron/__init__.py", line 24, in run
    asyncio.run(self.function(datetime.now()))
  File "/usr/lib/python3.11/asyncio/runners.py", line 190, in run
    return runner.run(main)
           ^^^^^^^^^^^^^^^^
  File "/usr/lib/python3.11/asyncio/runners.py", line 118, in run
    return self._loop.run_until_complete(task)
           ^^^^^^^^^^^^^^^^^^^^^^^^^^^^^^^^^^^
  File "/usr/lib/python3.11/asyncio/base_events.py", line 653, in run_until_complete
    return future.result()
           ^^^^^^^^^^^^^^^
  File "/var/pythonapps/downloadFiles.py", line 163, in downloadFiles
    ModifyFiles().domitechMod() #
    ^^^^^^^^^^^^^^^^^^^^^^^^^
  File "/var/pythonapps/Classes/ModifyFiles.py", line 120, in actionMod
    subst_dict['ean'] = item['EAN']
                        ~~~~^^^^^^^
KeyError: 'EAN'
Exception in thread Thread-86:
Traceback (most recent call last):
  File "/usr/lib/python3.11/threading.py", line 1038, in _bootstrap_inner
    self.run()
  File "/var/pythonapps/.venv/lib/python3.11/site-packages/pycron/__init__.py", line 24, in run
    asyncio.run(self.function(datetime.now()))
  File "/usr/lib/python3.11/asyncio/runners.py", line 190, in run
    return runner.run(main)
           ^^^^^^^^^^^^^^^^
  File "/usr/lib/python3.11/asyncio/runners.py", line 118, in run
    return self._loop.run_until_complete(task)
           ^^^^^^^^^^^^^^^^^^^^^^^^^^^^^^^^^^^
  File "/usr/lib/python3.11/asyncio/base_events.py", line 653, in run_until_complete
    return future.result()
           ^^^^^^^^^^^^^^^
  File "/var/pythonapps/downloadFiles.py", line 163, in downloadFiles
    ModifyFiles().domitechMod() #
    ^^^^^^^^^^^^^^^^^^^^^^^^^
  File "/var/pythonapps/Classes/ModifyFiles.py", line 120, in actionMod
    subst_dict['ean'] = item['EAN']
                        ~~~~^^^^^^^
KeyError: 'EAN'
Exception in thread Thread-89:
Traceback (most recent call last):
  File "/usr/lib/python3.11/threading.py", line 1038, in _bootstrap_inner
    self.run()
  File "/var/pythonapps/.venv/lib/python3.11/site-packages/pycron/__init__.py", line 24, in run
    asyncio.run(self.function(datetime.now()))
  File "/usr/lib/python3.11/asyncio/runners.py", line 190, in run
    return runner.run(main)
           ^^^^^^^^^^^^^^^^
  File "/usr/lib/python3.11/asyncio/runners.py", line 118, in run
    return self._loop.run_until_complete(task)
           ^^^^^^^^^^^^^^^^^^^^^^^^^^^^^^^^^^^
  File "/usr/lib/python3.11/asyncio/base_events.py", line 653, in run_until_complete
    return future.result()
           ^^^^^^^^^^^^^^^
  File "/var/pythonapps/downloadFiles.py", line 163, in downloadFiles
    ModifyFiles().domitechMod() #
    ^^^^^^^^^^^^^^^^^^^^^^^^^
  File "/var/pythonapps/Classes/ModifyFiles.py", line 120, in actionMod
    subst_dict['ean'] = item['EAN']
                        ~~~~^^^^^^^
KeyError: 'EAN'
Exception in thread Thread-90:
Traceback (most recent call last):
  File "/usr/lib/python3.11/threading.py", line 1038, in _bootstrap_inner
    self.run()
  File "/var/pythonapps/.venv/lib/python3.11/site-packages/pycron/__init__.py", line 24, in run
    asyncio.run(self.function(datetime.now()))
  File "/usr/lib/python3.11/asyncio/runners.py", line 190, in run
    return runner.run(main)
           ^^^^^^^^^^^^^^^^
  File "/usr/lib/python3.11/asyncio/runners.py", line 118, in run
    return self._loop.run_until_complete(task)
           ^^^^^^^^^^^^^^^^^^^^^^^^^^^^^^^^^^^
  File "/usr/lib/python3.11/asyncio/base_events.py", line 653, in run_until_complete
    return future.result()
           ^^^^^^^^^^^^^^^
  File "/var/pythonapps/downloadFiles.py", line 163, in downloadFiles
    ModifyFiles().domitechMod() #
    ^^^^^^^^^^^^^^^^^^^^^^^^^
  File "/var/pythonapps/Classes/ModifyFiles.py", line 120, in actionMod
    subst_dict['ean'] = item['EAN']
                        ~~~~^^^^^^^
KeyError: 'EAN'
Exception in thread Thread-92:
Traceback (most recent call last):
  File "/usr/lib/python3.11/threading.py", line 1038, in _bootstrap_inner
    self.run()
  File "/var/pythonapps/.venv/lib/python3.11/site-packages/pycron/__init__.py", line 24, in run
    asyncio.run(self.function(datetime.now()))
  File "/usr/lib/python3.11/asyncio/runners.py", line 190, in run
    return runner.run(main)
           ^^^^^^^^^^^^^^^^
  File "/usr/lib/python3.11/asyncio/runners.py", line 118, in run
    return self._loop.run_until_complete(task)
           ^^^^^^^^^^^^^^^^^^^^^^^^^^^^^^^^^^^
  File "/usr/lib/python3.11/asyncio/base_events.py", line 653, in run_until_complete
    return future.result()
           ^^^^^^^^^^^^^^^
  File "/var/pythonapps/downloadFiles.py", line 163, in downloadFiles
    ModifyFiles().domitechMod() #
    ^^^^^^^^^^^^^^^^^^^^^^^^^
  File "/var/pythonapps/Classes/ModifyFiles.py", line 120, in actionMod
    subst_dict['ean'] = item['EAN']
                        ~~~~^^^^^^^
KeyError: 'EAN'
Exception in thread Thread-1:
Traceback (most recent call last):
  File "/usr/lib/python3.11/threading.py", line 1038, in _bootstrap_inner
    self.run()
  File "/var/pythonapps/.venv/lib/python3.11/site-packages/pycron/__init__.py", line 24, in run
    asyncio.run(self.function(datetime.now()))
  File "/usr/lib/python3.11/asyncio/runners.py", line 190, in run
    return runner.run(main)
           ^^^^^^^^^^^^^^^^
  File "/usr/lib/python3.11/asyncio/runners.py", line 118, in run
    return self._loop.run_until_complete(task)
           ^^^^^^^^^^^^^^^^^^^^^^^^^^^^^^^^^^^
  File "/usr/lib/python3.11/asyncio/base_events.py", line 653, in run_until_complete
    return future.result()
           ^^^^^^^^^^^^^^^
  File "/var/pythonapps/downloadFiles.py", line 162, in downloadFiles
    ModifyFiles().actionMod() #
    ^^^^^^^^^^^^^^^^^^^^^^^^^
  File "/var/pythonapps/Classes/ModifyFiles.py", line 120, in actionMod
    subst_dict['ean'] = item['EAN']
                        ~~~~^^^^^^^
KeyError: 'EAN'
